Workbook

Sheet data
A1: 구분
A2: 지정일자
A3: 국가유산명 | B3: 보령 성주사지
A4: 수량
A5: 소유자
A6: 관리자
A7: 국가유산 정보
A8: 용역명 | B8: ㅇㅇㅇㅇㅇㅇㅇㅇㅇ
A9: 시행연도
A10: 시행연월
A11: 발주청
A12: 소관부서
A13: 사업비 | B13: 55000000
A14: 용역기간 | B14: 60
A15: 설계내용 | B15: ㅇㅇㅇㅇㅇㅇㅇㅇㅇㅇㅇ
A16: 지침 | B16: ㅇㅇㅇㅇㅇㅇㅇㅇㅇㅇㅇㅇ
A17: 사업비(VAT 제외) | B17: 50000000
A18: 설계용역비(공급가액) | B18: 8545000
A19: 손해배상보험료 | B19: 3691000
A20: 부가가치세 | B20: 1223600
A21: 총 용역비(VAT 포함) | B21: 13459600
A22: 공사종류(보험) | B22: 관람집회시설공사
A23: 표준공사기간(일) | B23: 1095
A24: 실제공사기간(일) | B24: 120
A25: 절사단위(보험료) | B25: 천원미만 절사
A26: sn | B26: 6
A27: no | B27: 3120
A28: ccmaName | B28: 사적
A29: ccbaMnm1 | B29: 보령 성주사지
A30: ccbaMnm2 | B30: 保寧 聖住寺址
A31: ccbaCtcdNm | B31: 충청남도
A32: ccsiName | B32: 보령시
A33: ccbaAdmin | B33: 보령시
A34: ccbaKdcd | B34: 13
A35: ccbaCtcd | B35: 34
A36: ccbaAsno | B36: 0003070000000
... A50: ccbaPoss | B50: 보령시 등
A51: ccbaCndt
A52: imageUrl | B52: http://www.khs.go.kr/unisearch/images/history_site/1626604.jpg
A53: content | B53: 보령 성주산 남쪽 기슭에 있는 9산선문의 하나인 성주사가 있던 자리이다. 백제 법왕 때 처음 지어졌는데 당시에는 오합사(烏合寺)라고 부르다가, 신라 문성왕때 당나라에서 돌아온 낭혜화상이 절을 크게 중창하면서 성주사라고 하였다. 산골에 자리잡고 있는 절이지만 통일신라시대의 다른 절과는 달리 평지에 자리하는 가람의 형식을 택하였다. 절터에는 남에서부터 차례로 중문처, 석등, 5층석탑(보물), 금당건물과 그뒤에 동서로 나란히 서있는 동삼층석탑, 중앙 3층석탑(보물), 서 3층석탑(보물)가 있고 그 뒤에 강당이 자리하고 있다. 최치원의 사산비문 중 하나인 낭혜화상백월보광탑비(국보)도 절의 북서쪽에 있다. 발굴조사결과 건물의 초석, 통일신라시대의 흙으로 빚은 불상의 머리, 백제·통일신라·고려시대의 기와 등 많은 유물이 출토되었다. 성주사는 당대 최대의 사찰이었으며, 최치원이 쓴 낭혜화상백월보광탑비는 신라 석비 중 가장 큰 작품으로 매우 중요한 학술적 가치를 지닌다. &lt;br/&gt;&lt;b&gt;※(성주사지 → 보령 성주사지)으로 명칭변경 되었습니다.(2011.07.28 고시)&lt;/b&gt;
...

Sheet 겉표지
D4: =VLOOKUP("ccmaName",data!$A$1:$B$270,2,0) -> 사적
A5: =VLOOKUP("용역명",data!$A$1:$B$270,2,0) -> ㅇㅇㅇㅇㅇㅇㅇㅇㅇ
A6: 실시설계용역 내역서
P12: =TEXT(DATE(LEFT(VLOOKUP("설계용역시행연월",data!$A$1:$B$270,2,0),4),RIGHT(VLOOKUP("설계용역시행연월",data!$A$1:$B$270,2,0),2),0),"yyyy.mm.") -> 2025.10.
P17: =VLOOKUP("지자체명",data!$A$1:$B$270,2,0)&"("&VLOOKUP("부서명",data!$A$1:$B$270,2,0)&")" -> 보령시(관광과)

Sheet 표지
A1: =TEXT(DATE(LEFT(VLOOKUP("설계용역시행연월",data!$A$1:$B$270,2,0),4),RIGHT(VLOOKUP("설계용역시행연월",data!$A$1:$B$270,2,0),2),0),"yyyy년 mm월") -> 2025년 10월 | E1: 과 장 | K1: 팀 장 | Q1: 검토자 | W1: 담당자
A5: =겉표지!A5 -> ㅇㅇㅇㅇㅇㅇㅇㅇㅇ
A6: 실시설계용역 내역서
E9: □ 용역개요
F10: ○ 실시설계 | N10: 1 | P10: 식
E14: □ 용 역 비: | K14: =V14 -> 9430000 | V14: =설계용역내역서!G10 -> 9430000
I17: 보 령 시

Sheet 예정공정표
A1: □ 예정공정표
A3: 공기 | B3: ="착수일로부터 "&data!B14&"일간" -> 착수일로부터 60일간 | H3: 누계 | I3: 비고
A5: 공종 | B5: 5일 | C5: 10일 | D5: 15일 | E5: =data!B14/2&"일" -> 30일 | F5: =(data!B14-5)&"일" -> 55일 | G5: =data!B14&"일" -> 60일
A6: 현 장 조 사 | H6: 5
A7: 자 료 수 집
A9: 관련법 검토 | H9: 10
A12: 설계검토 및 | H12: =data!B14/2 -> 30
A13: 현상변경 심의
A15: 실시설계 | H15: =(data!B14-5) -> 55
A18: 성과품 작성 | H18: =data!B14 -> 60
A21: 누 계 | B21: 5 | C21: 10 | D21: 15 | E21: =data!B14/2 -> 30 | F21: =(data!B14-5) -> 55 | G21: =data!B14 -> 60 | H21: =data!B14 -> 60
A22: 비 고

Sheet 용역 설명서
A1: Ⅰ. 용 역 설 명 서
A3: 1. 용 역 명 : | C3: =겉표지!A5 -> ㅇㅇㅇㅇㅇㅇㅇㅇㅇ
A5: 2. 국가유산 정보
B6: - 국가유산명 | D6: =VLOOKUP("ccbaMnm1",data!$A$1:$B$270,2,0) -> 보령 성주사지
B7: - 구분 | D7: =VLOOKUP("ccmaName",data!$A$1:$B$270,2,0)&"("&TEXT(DATE(LEFT(VLOOKUP("ccbaAsdt",data!$A$1:$B$270,2,0),4),MID(VLOOKUP("ccbaAsdt",data!$A$1:$B$270,2,0),5,2),RIGHT(VLOOKUP("ccbaAsdt",data!$A$1:$B$270,2,0),2)),"yyyy.mm.dd.")&")" -> 사적(1984.08.13.)
B8: - 수량 | D8: =VLOOKUP("ccbaQuan",data!$A$1:$B$270,2,0) -> 67,295㎡
B9: - 소유자/관리자 | D9: =VLOOKUP("ccbaPoss",data!$A$1:$B$270,2,0)&" / "&VLOOKUP("ccbaAdmin",data!$A$1:$B$270,2,0) -> 보령시 등 / 보령시
B10: - 내용
B11: =VLOOKUP("content",data!$A$1:$B$270,2,0) -> 보령 성주산 남쪽 기슭에 있는 9산선문의 하나인 성주사가 있던 자리이다. 백제 법왕 때 처음 지어졌는데 당시에는 오합사(烏合寺)라고 부르다가, 신라 문성왕때 당나라에서 돌아온 낭혜화상이 절을 크게 중창하면서 성주사라고 하였다. 산골에 자리잡고 있는 절이지만 통일신라시대의 다른 절과는 달리 평지에 자리하는 가람의 형식을 택하였다. 절터에는 남에서부터 차례로 중문처, 석등, 5층석탑(보물), 금당건물과 그뒤에 동서로 나란히 서있는 동삼층석탑, 중앙 3층석탑(보물), 서 3층석탑(보물)가 있고 그 뒤에 강당이 자리하고 있다. 최치원의 사산비문 중 하나인 낭혜화상백월보광탑비(국보)도 절의 북서쪽에 있다. 발굴조사결과 건물의 초석, 통일신라시대의 흙으로 빚은 불상의 머리, 백제·통일신라·고려시대의 기와 등 많은 유물이 출토되었다. 성주사는 당대 최대의 사찰이었으며, 최치원이 쓴 낭혜화상백월보광탑비는 신라 석비 중 가장 큰 작품으로 매우 중요한 학술적 가치를 지닌다. &lt;br/&gt;&lt;b&gt;※(성주사지 → 보령 성주사지)으로 명칭변경 되었습니다.(2011.07.28 고시)&lt;/b&gt;
A12: 2. 소 재 지 : | C12: =VLOOKUP("ccbaLcad",data!$A$1:$B$270,2,0) -> 충남 보령시 성주면 성주리 72번지
A14: 3. 사업내용 : | C14: =data!B8 -> ㅇㅇㅇㅇㅇㅇㅇㅇㅇ
A16: 4. 과업범위 : | C16: =VLOOKUP("설계내용",data!$A$1:$B$270,2,0) -> ㅇㅇㅇㅇㅇㅇㅇㅇㅇㅇㅇ
A18: 5. 사업지침(자세한 사항은 관계 공무원의 설명을 들을 것)
A19: ="◦ "&VLOOKUP("지침",data!$A$1:$B$270,2,0) -> ◦ ㅇㅇㅇㅇㅇㅇㅇㅇㅇㅇㅇㅇ
A22: 6. 용역기간 : | C22: =예정공정표!B3 -> 착수일로부터 60일간

Sheet Sheet3
A1: Ⅱ. 과업의 범위
A3: 1. 설계 일반조건
A4: 가. 설계용역을 수행함에 있어 국가유산수리공사 설계도서 작성기준(국가유산청, 충남도) 및 이에 수행의 목적상 따라야 하는 관계규정에 먼저 준수하여야하며, 필요에 따라 관계기관과 협의해야 한다.
A5: - 관계규정 -
A6: ○ 성곽의 보존과 관리에 관한 일반지침(훈령)
A7: ○ 사적 종합정비계획의 수립 및 시행에 관한 지침(훈령)
A8: ○ 천연기념물(식물) 관리지침(훈령)
A9: ○ 역사적 건축물과 유적의 수리복원 및 관리에 관한 일반원칙(매뉴얼)
A10: ○ 서원의 보존과 관리에 관한 일반지침(훈령)
A11: ○ 국가유산수리 등에 관한 업무지침(고시)
A12: ○ 국가유산수리 설계도서 작성기준(고시)
A13: 나. 본 설계기간 중 과업지시는 성실히 수행하여야 하며, 지침 및 과업에 명시되지 않은 사항이라도 발주청(보령시 관광과)의 시정요구가 있을시는 바로 수행하고, 과업자(용역자)의 의견이나 건의사항을 협의처리하되, 이에 따른 추가비용은 청구할 수 없다.
... A24: 가. 기본원칙 : 「문화재수리규범」의 준수
B25: 문화재수리규범
A27: 1. 원래의 양식을 변형시키지 않는다.
A28: 2. 원래의 사용재료를 훼손시키지 않는다.
A29: 3. 전통기법으로 수리한다.
A30: 4. 재료의 대체가 허용되는 경우는 다음과 같다.
A31: 4.1 문화재를 그대로 둘 경우, 붕괴·소멸되어 새로운 재료의 사용이 불가피한 경우
A32: 4.2 보강 없이는 위험을 피할 수 없는 경우
A33: 5. 문화재가 지닌 특성을 간직한 채 전체적으로 조화가 유지되도록 하여야 한다.
A34: 6. 수리대상물은 수리하기 전의 상태와 수리 후 상세한 기록을 작성하고 수리절차와 처리방법 등 수리 내용을 구체적으로 기록
A35: 하여 보고서로 남긴다.
A36: 7. 문화재 수리 내용을 모두 기록 보존하고, 문화재를 파손시키거나 변형하지 않도록 한다.
A37: 8. 수리는 필요불가결한 경우에 최소한으로 한다.
A38: 9. 모든 수리는 원형보존의 원칙을 준수하되 구조적으로 안전하여야 한다.
... A40: 1) 설계도서는「문화재수리규범」을 준수하여 공사명, 목차, 설계설명서, 공사시방서, 내역서, 수량산출서, 설계도면, 현황사진첩을 포함하여 작성하며, 작성항목은 다음과 같다.
A41: 구분 | D41: 작성 도서 | E41: 작성 내용 | F41: 축척
A42: 일반 | D42: 표지 | E42: ․공사명칭, 공사구분, 작성년월, 설계사무소 명칭, 발주처 명칭
A43: 사항 | D43: 목차 | E43: ․일반사항, 설계설명서, 공사시방서, 예정공정표, 내역서, 수량산출서, 설계도면, 현황사진첩
A44: 설 계 | D44: 개요 | E44: ․공사명, 지정별, 소재지, 공사목적, 사업지침, 소요예산, 기간, 규모, 물량, 자재현황, 자재원, 관급자재 등
A45: 설명서 | D45: 연혁 | E45: ․창건, 중건년도, 관련인물, 관련 전설 등
E46: ․보수정비 이력(년도, 보수범위, 보수내용)
D47: 현황 | E47: ․주변현황 : 국가유산 보존에 유·무형으로 영향을 줄 수 있는 환경, 지형, 배수관계, 경역 내 건물배치 현황, 관련 경역 면적 등 공사와 관계있는 지형, 등고, 토질, 수목생태 등
E48: ․보수대상현황 : 보수대상물의 구조, 보존상태, 퇴락부위, 훼손부위, 퇴락원인, 변형부분 등
D49: 고증 | E49: ․보수, 복원 시 원형고증 관련 내용
D50: 설계변경 조건 | E50: ․설계변경 사유
A51: 공사시방서 | E51: ․공사의 특수성, 지역 여건, 공사 방법 등 공사대상의 특징 및 특이사항(※ [별표4]에 별도 기준 제시)
A52: 특기시방서 | E52: ․표준시방서에서 규정하지 않은 특기 사항
A53: 예정공정표 | E53: ․공사 일정, 작업량 등의 시공 계획
...

Sheet 설계용역내역서
A1: □ 내역서
A2: N0 | B2: 공 종 | C2: 규 격 | D2: 수 량 | E2: 단위 | F2: 계 | H2: 노 무 비 | J2: 재 료 비 | L2: 경 비 | N2: 비 고
F3: 단 가 | G3: 금 액 | H3: 단 가 | I3: 금 액 | J3: 단 가 | K3: 금 액 | L3: 단 가 | M3: 금 액
A4: =표지!A5 -> ㅇㅇㅇㅇㅇㅇㅇㅇㅇ
A5: 1. | B5: 실시설계 | C5: ="공사비("&TEXT('산근1(실시설계요율)'!V9,"#,###")&"원)의 "&'산근1(실시설계요율)'!O24&"%" -> 공사비(50,000,000원)의 17.09% | D5: 1 | E5: 식 | G5: =M5 -> 8545000 | L5: ='산근1(실시설계요율)'!W25 -> 8545000 | M5: =INT(L5*D5) -> 8545000
B6: 공 급 가 액 | D6: 1 | E6: 식 | G6: =G5 -> 8545000
A7: 2. | B7: 손해보험료 | C7: ="공급가액의 "&'기초2(손해배상공제요율)'!C5&"%" -> 공급가액의 0.432% | D7: 1 | E7: 식 | G7: =+I7+K7+M7 -> 36000 | L7: ='산근2(손해보험공제요율)'!H17 -> 36000 | M7: =L7 -> 36000
A8: 3. | B8: 부가가치세 | C8: (1+2)*10% | D8: 1 | E8: 식 | G8: =(G6+G7)*10% -> 858100
B9: 합 계 | C9: 1+2+3 | G9: =G7+G8+G6 -> 9439100
B10: 적 용 | G10: =ROUNDDOWN(G9,-4) -> 9430000 | H10: (단수조정)

Sheet 산출근거표지
A6: 산 출 근 거

Sheet 산근1(실시설계요율)
AH1: 구분
A2: □ 실시설계요율 산출 | AH2: 0
AH3: 0
B4: 1. 개략공사비 | AH4: 0 | AP4: 0 | AQ4: 0 | AR4: 0.3 | AS4: 0.3
B5: 구 분 | L5: 수량 | P5: 단위 | R5: 공사내용 | V5: 공 사 비 | AC5: 비 고 | AH5: 0 | AP5: 3천만원 이하 | AQ5: 0.3 | AR5: 0.3 | AS5: 0.5
B6: =표지!A5 -> ㅇㅇㅇㅇㅇㅇㅇㅇㅇ | L6: 1 | O6: 식 | R6: ='용역 설명서'!C14 -> ㅇㅇㅇㅇㅇㅇㅇㅇㅇ | V6: =data!B13 -> 55000000 | AH6: 0 | AI6: =data!B13 | AP6: 5천만원 | AQ6: 0.5 | AR6: 0.5 | AS6: 1
AH7: 0 | AP7: 1억원 | AQ7: 1 | AR7: 1 | AS7: 2
B8: 소 계 | V8: =SUM(V6:AB7) -> 55000000 | AC8: 부가세 포함 | AH8: 0 | AP8: 2억원 | AQ8: 2 | AR8: 2 | AS8: 3
B9: 적 용 | V9: =ROUNDDOWN(V8/1.1,0) -> 50000000 | AC9: 부가세 제외 | AH9: 0 | AP9: 3억원 | AQ9: 3 | AR9: 3 | AS9: 5
AH10: 0 | AP10: 5억원 | AQ10: 5 | AR10: 5 | AS10: 10
B11: 2. 실시설계 설계비요율 산정 | AH11: 0 | AI11: =ROUNDDOWN(V9*0.00000001,1) -> 0.5 | AP11: 10억원 | AQ11: 10 | AR11: 10 | AS11: 20
B12: 가. 요율산출근거 : 문화재청 고시 제2024-16호 국가유산수리 설계 대가기준, 2024. 1. 8. | AH12: 0 | AP12: 20억원 | AQ12: 20 | AR12: 20 | AS12: 30
B13: 나. 실시설계 요율 : | I13: =VLOOKUP("설계난이도",data!$A$1:$B$270,2,0) -> 복잡 | K13: 공정으로 적용한다. | AH13: 0 | AP13: 30억원 | AQ13: 30 | AR13: 30 | AS13: 100
AH14: 1 | AP14: 50억원 | AR14: 100
B15: - 공사비 | F15: =LOOKUP(ROUNDDOWN($V$9*0.00000001,1),$AQ$4:$AQ$16,$AR$4:$AR$16) -> 0.5 | H15: 억원 까지 : | L15: =VLOOKUP(AJ15,'기초1(요율적용기준) '!$M$5:$N$41,2,0) -> 17.09 | N15: % | P15: (국가유산 수리 부문) | AH15: 0 | AI15: =IF(V9*0.00000001>100,200,IF(V9*0.00000001>50,100,IF(V9*0.00000001>30,50,IF(V9*0.00000001>20,30,IF(V9*0.00000001>10,20,IF(V9*0.00000001>5,10,IF(V9*0.00000001>3,5,IF(V9*0.00000001>2,3,IF(V9*0.00000001>1,2,IF(V9*0.00000001>0.5,1,IF(V9*0.00000001>0.3,0.5,IF(ROUNDDOWN(V9*0.00000001,-1)=0,0.3,ROUNDDOWN(V9*0.00000001,0))))))))))))) -> 0.5 | AJ15: =F15&" "&$I$13 -> 0.5 복잡 | AK15: 삭제하지 마세요 | AP15: 100억원 | AQ15: 100 | AR15: 100 | AS15: 200
B16: - 공사비 | F16: =IF(AND(F15*100000000=V9),F15,LOOKUP(ROUNDDOWN($V$9*0.00000001,1),$AQ$4:$AQ$16,$AS$4:$AS$16)) -> 0.5 | H16: 억원 까지 : | L16: =VLOOKUP(AJ16,'기초1(요율적용기준) '!$M$5:$N$41,2,0) -> 17.09 | N16: % | P16: (국가유산 수리 부문) | AH16: =IF(AND(F15=F16,F16=0.3),1,0) -> 0 | AJ16: =F16&" "&$I$13 -> 0.5 복잡 | AP16: 200억원 | AQ16: 200 | AR16: 200 | AS16: 200
B17: 다. 공 사 비 : | H17: =V9 -> 50000000 | M17: 원에 대한 요율 산정 | AH17: 0 | AJ17: 1
B18: 라. 적용요율(직선보간법에 의해 계산) | AH18: 0
D19: : | E19: =L15 -> 17.09 | H19: - | I19: ( | J19: =H17 -> 50000000 | O19: - | P19: =F15*100000000 -> 50000000 | U19: ) | V19: × | W19: ( | X19: =L15 -> 17.09 | Z19: - | AB19: =L16 -> 17.09 | AD19: ) | AH19: 0
M20: ( | N20: =F16*100000000 -> 50000000 | T20: - | U20: =F15*100000000 -> 50000000 | Z20: ) | AH20: 0
E21: = | F21: =IFERROR(ROUND(E19-((J19-P19)*(X19-AB19))/(N20-U20),3), E19) -> 17.09 | AH21: 0
AH22: 0
B23: 마. 실시설계비 산정 | AH23: 0
C24: =V9 -> 50000000 | K24: × | O24: =F21 -> 17.09 | R24: % | S24: × | T24: =AJ17 -> 1 | V24: = | W24: =ROUNDDOWN(C24*O24%*T24,0) -> 8545000 | AA24: 원 | AH24: 0
T25: 적용 | W25: =TRUNC(W24,-3) -> 8545000 | AA25: 원 | AH25: 0 | AI25: 실시설계비 | AJ25: 공사비 | AK25: 합계
AH26: 0 | AI26: =설계용역내역서!G10 -> 9430000 | AJ26: =V6 -> 55000000 | AK26: =AI26+AJ26 -> 64430000

Sheet 산근2(실시설계요율 3천 이하)
A1: □ 실시설계요율 산출
B3: 1. 개략공사비
B4: 구 분 | L4: 수량 | P4: 단위 | R4: 시설규모 | V4: 공 사 비 | AC4: 비 고
B5: =표지!A5 -> ㅇㅇㅇㅇㅇㅇㅇㅇㅇ | L5: 1 | O5: 식 | V5: 25300000
B7: 소 계 | V7: =SUM(V5:AB6) -> 25300000 | AC7: 부가세 포함
B8: 적 용 | V8: =TRUNC(V7/1.1,-3) -> 23000000 | AC8: 부가세 제외
B10: 2. 실시설계 설계비요율 산정
B11: 가. 요율산출근거 : 문화재청 고시 제2024-16호 국가유산수리 설계 대가기준, 2024. 1. 8.
B12: 나. 실시설계 요율 : | I12: 보통 | K12: 공정으로 적용한다.
R13: 실시설계요율의 | W13: 1 | Y13: 배 적용한다
B14: - 공사비 | F14: 0.3 | H14: 억원 까지 : | L14: =VLOOKUP(AH14,'기초1(요율적용기준) '!$M$5:$N$41,2,0) -> 16.94 | N14: % | P14: (문화재 부문) | AH14: =F14&" "&$I$12 -> 0.3 보통
B15: - 공사비 | F15: 0.5 | H15: 억원 까지 : | L15: =VLOOKUP(AH15,'기초1(요율적용기준) '!$M$5:$N$41,2,0) -> 15.54 | N15: % | P15: (문화재 부문) | AH15: =F15&" "&$I$12 -> 0.5 보통
B16: 다. 공 사 비 : | H16: =ROUND(V8*0.001,1) -> 23000 | L16: 천원에 대한 요율 산정
B17: 라. 적용요율(직선보간법에 의해 계산) | N17: : | O17: =L14 -> 16.94 | Q17: % | R17: (3천만원 이하)
D18: : | E18: =L14 -> 16.94 | H18: - | I18: ( | J18: =H16*1000 -> 23000000 | O18: - | P18: =F14*100000000 -> 30000000 | U18: ) | V18: × | W18: ( | X18: =L14 -> 16.94 | Z18: - | AB18: =L15 -> 15.54 | AD18: )
M19: ( | N19: =F15*100000000 -> 50000000 | T19: - | U19: =F14*100000000 -> 30000000 | Z19: )
E20: = | F20: =ROUND(E18-((J18-P18)*(X18-AB18))/(N19-U19),3) -> 17.43
B22: 마. 실시설계비 산정
C23: =V8 -> 23000000 | K23: × | O23: =O17 -> 16.94 | R23: % | S23: × | T23: =W13 -> 1 | V23: = | W23: =ROUNDDOWN(C23*O23%*T23,0) -> 3896200 | AA23: 원
T24: 적용 | W24: =TRUNC(W23,-3) -> 3896000 | AA24: 원 | AG24: 실시설계비 | AH24: 공사비 | AI24: 합계
AG25: =설계용역내역서!G10 -> 9430000 | AH25: =V5 -> 25300000 | AI25: =AG25+AH25 -> 34730000

Sheet 기초1(요율적용기준) 
A1: [별표1] 국가유산수리 설계대가 요율(제6조 관련) | I1: 복잡
I2: 보통
B3: 공사비 | C3: 국가유산수리 설계대가 요율(%) | F3: 비고 | I3: 단순
C4: 복 잡 | D4: 보 통 | E4: 단 순 | K4: 복잡
B5: 3천만원 이하 | C5: 18.63 | D5: 16.94 | E5: 15.25 | I5: 0.3 | J5: 복잡 | K5: 18.63 | M5: =I5&" "&J5 -> 0.3 복잡 | N5: 18.63
B6: 5천만원 | C6: 17.09 | D6: 15.54 | E6: 13.99 | I6: 0.5 | J6: 복잡 | K6: 17.09 | M6: =I6&" "&J6 -> 0.5 복잡 | N6: 17.09
B7: 1억원 | C7: 15.2 | D7: 13.82 | E7: 12.44 | I7: 1 | J7: 복잡 | K7: 15.2 | M7: =I7&" "&J7 -> 1 복잡 | N7: 15.2
B8: 2억원 | C8: 13.53 | D8: 12.3 | E8: 11.07 | I8: 2 | J8: 복잡 | K8: 13.53 | M8: =I8&" "&J8 -> 2 복잡 | N8: 13.53
B9: 3억원 | C9: 12.63 | D9: 11.48 | E9: 10.33 | I9: 3 | J9: 복잡 | K9: 12.63 | M9: =I9&" "&J9 -> 3 복잡 | N9: 12.63
B10: 5억원 | C10: 11.58 | D10: 10.53 | E10: 9.48 | I10: 5 | J10: 복잡 | K10: 11.58 | M10: =I10&" "&J10 -> 5 복잡 | N10: 11.58
B11: 10억원 | C11: 10.31 | D11: 9.37 | E11: 8.43 | I11: 10 | J11: 복잡 | K11: 10.31 | M11: =I11&" "&J11 -> 10 복잡 | N11: 10.31
B12: 20억원 | C12: 9.16 | D12: 8.33 | E12: 7.5 | I12: 20 | J12: 복잡 | K12: 9.16 | M12: =I12&" "&J12 -> 20 복잡 | N12: 9.16
B13: 30억원 | C13: 8.56 | D13: 7.78 | E13: 7 | I13: 30 | J13: 복잡 | K13: 8.56 | M13: =I13&" "&J13 -> 30 복잡 | N13: 8.56
B14: 50억원 | C14: 7.85 | D14: 7.14 | E14: 6.43 | I14: 50 | J14: 복잡 | K14: 7.85 | M14: =I14&" "&J14 -> 50 복잡 | N14: 7.85
B15: 100억원 | C15: 6.99 | D15: 6.35 | E15: 5.72 | I15: 100 | J15: 복잡 | K15: 6.99 | M15: =I15&" "&J15 -> 100 복잡 | N15: 6.99
B16: 200억원 | C16: 6.22 | D16: 5.65 | E16: 5.09 | I16: 200 | J16: 복잡 | K16: 6.22 | M16: =I16&" "&J16 -> 200 복잡 | N16: 6.22
B17: 200억원 초과 | C17: y=0.9674×-0.169 | I17: 0.3 | J17: 보통 | K17: 16.94 | M17: =I17&" "&J17 -> 0.3 보통 | N17: 16.94
C18: y : 해당공사비요율 x : 해당 금액 (단위 : 천원) | I18: 0.5 | J18: 보통 | K18: 15.54 | M18: =I18&" "&J18 -> 0.5 보통 | N18: 15.54
C19: ※ 복잡은 10% 가산, 단순은 10% 감산 | I19: 1 | J19: 보통 | K19: 13.82 | M19: =I19&" "&J19 -> 1 보통 | N19: 13.82
I20: 2 | J20: 보통 | K20: 12.3 | M20: =I20&" "&J20 -> 2 보통 | N20: 12.3
A21: ※ 공사비 단위는 천원으로서 그 이하의 금액은 절삭하여 산정한다. | I21: 3 | J21: 보통 | K21: 11.48 | M21: =I21&" "&J21 -> 3 보통 | N21: 11.48
A22: ※ 200억원 초과의 경우 공식에 의해 산출된 요율은 소수점 셋째자리에서 반올림한다. | I22: 5 | J22: 보통 | K22: 10.53 | M22: =I22&" "&J22 -> 5 보통 | N22: 10.53
A23: ※ 공사비는 개별 수리 공사에 대한 비용으로 서로 다른 둘 이상의 국가유산 수리 공사비를 한 건으로 산출하여 적용하지 않는다. | I23: 10 | J23: 보통 | K23: 9.37 | M23: =I23&" "&J23 -> 10 보통 | N23: 9.37
A24: ※ 국가유산수리의 난이도는 단순, 보통 및 복잡으로 다음과 같이 구분한다. | I24: 20 | J24: 보통 | K24: 8.33 | M24: =I24&" "&J24 -> 20 보통 | N24: 8.33
A25: 주: 1) 법에 따른 국가유산수리 외에도 전통양식으로 하는 경우는 동 기준을 적용할 수 있다. | I25: 30 | J25: 보통 | K25: 7.78 | M25: =I25&" "&J25 -> 30 보통 | N25: 7.78
A26: 2) 단순ㆍ보통ㆍ복잡 국가유산수리가 동일한 현장인 경우 최상위 난이도를 기준으로 산출한다. | I26: 50 | J26: 보통 | K26: 7.14 | M26: =I26&" "&J26 -> 50 보통 | N26: 7.14
I27: 100 | J27: 보통 | K27: 6.35 | M27: =I27&" "&J27 -> 100 보통 | N27: 6.35
A28: 분류기준 | I28: 200 | J28: 보통 | K28: 5.65 | M28: =I28&" "&J28 -> 200 보통 | N28: 5.65
A29: 구분 | B29: 지정유산 수리* | D29: 주변정비** | F29: 비고 | I29: 0.3 | J29: 단순 | K29: 15.25 | M29: =I29&" "&J29 -> 0.3 단순 | N29: 15.25
A30: 단순 | D30: ① 목조건축물의 부분 해체ㆍ보수 * 산자이상 해체와 그보다 적은 범위의 해체보수 (지붕 번와공사, 개판 또는 산자 교체 포함) * 목조건축물의 단일 공종 보수 (지붕, 전돌, 미장, 창호, 온돌, 수장, 단청 등) * 사주문, 협문 등과 같은 소규모(바닥면적 10㎡ 이하) 건축물 ② 성곽, 탑 등 석조물, 유구정비 * 성곽 : 읍성(자연석 석성)의 부분 해체보수 * 탑 등 석조물 : 고려시대 이후 석탑 등 석조물의 부분 해체보수, 평석교(단순 구조), 승탑, 석조의 부분 해체보수 * 유구정비 : 같은 시기의 유구로 규모가 작고 단일공종의 경우 ③ 도로, 담장(꽃담, 궁담 제외), 석축, 단순 조경식재 등 부속시설 등의 정비 | I30: 0.5 | J30: 단순 | K30: 13.99 | M30: =I30&" "&J30 -> 0.5 단순 | N30: 13.99
A31: 보통 | B31: ① 목조건축물의 해체ㆍ보수 * 산자이상 해체와 그보다 적은 범위의 해체보수 (지붕 번와공사, 개판 또는 산자 교체 포함) * 목조건축물 단일 공종 보수 (지붕, 전돌, 미장, 창호, 온돌, 수장, 단청 등) * 사주문, 협문 등과 같은 소규모(바닥면적 10㎡ 이하) 건축물 ② 성곽, 탑 등 석조물, 유구정비 * 성곽 : 읍성(자연석 석성)의 부분 해체보수 * 탑 등 석조물 : 고려시대 이후 석탑 등 석조물의 부분 해체보수, 평석교(단순 구조), 승탑, 석조의 일부 해체보수 * 유구정비 : 같은 시기의 유구로 규모가 작고 단일공종인 경우 ③ 국가유산수리업*** 1종이 수리할 수 있는 국가유산수리 ④ 도로, 담장, 석축, 조경식재 등 부속시설의 정비 | D31: ① 목조건축물의 해체ㆍ보수 * 5량가 이상 : 연목과 도리 일부 이상 해체보수 * 5량가 미만(주심포, 다포 제외) : 전면해체보수, 신축, 복원, 이전 * 목조건축물의 상호 연계성이 있는 2개 공종 이상의 복합공사 (예 : 목공사와 단청공사, 연목 해체보수와 지붕공사) * 화장실이나 부속건물의 신축, 복원, 이전 ② 성곽, 탑 등 석조물, 유구정비 * 성곽 : 읍성(자연석 석성)의 전면해체보수, 가공석을 사용한 석성이나 홍예의 부분해체보수 * 탑 등 석조물 : 고려시대 전 석탑, 전탑 등 석조물의 부분 해체보수 고려시대 이후 석탑 등 석조물의 완전 해체보수 * 유구정비 : 시기가 다른 유구로 복합 공종일 경우 ③ 복합 공종의 주변정비시설, 조경시설물 및 조경식재 : 꽃담, 궁담 등 담장공사, 전통기법에 의한 조경공사(식재, 연못 조성 등) ④ 국가유산수리업*** 2종 이상이 복합된 국가유산수리 | I31: 1 | J31: 단순 | K31: 12.44 | M31: =I31&" "&J31 -> 1 단순 | N31: 12.44
A32: 구분 | B32: 지정유산 수리* | D32: 주변정비** | F32: 비고 | I32: 0.3 | J32: 단순 | K32: 15.25 | M32: =I32&" "&J32 -> 0.3 단순 | N32: 15.25
A33: 복잡 | B33: ① 목조건축물의 해체ㆍ보수 * 연목과 도리 일부 이상 해체보수 * 목조건축물의 상호 연계성이 있는 2개 공종 이상의 복합공사 (예 : 목공사와 단청공사, 연목 해체보수와 지붕공사) ② 성곽, 탑 등 석조물, 유구정비 * 성곽 : 읍성(자연석 석성)의 전면 해체보수 가공석을 사용한 석성이나 홍예의 부분 해체보수 * 탑 등 석조물 : 고려시대 전 석탑, 전탑 등 석조물의 해체보수 고려시대 이후 석탑 등 석조물의 완전 해체보수 * 유구정비 : 시기가 다른 유구로 복합공종일 경우 ③ 국가유산수리업*** 2종 이상이 복합된 국가유산수리 ④ 기념관, 전시관, 박물관 등 신축, 복원, 이전 ⑤ 특수한 양식 등 고도의 전문성을 요하는 수리로 발주자가 인정한 경우 | D33: ① 목조건축물의 해체ㆍ보수 * 연목이상 해체보수하는 경우로 도리와 공포까지 보수하는 경우 * 익공계, 주심포, 다포계 건물의 신축, 복원, 이전 ② 성곽, 탑 등 석조물 * 성곽 : 가공석을 사용한 석성, 홍예의 전면 해체보수 * 탑 등 석조물 : 고려시대 이전 석탑, 전탑 등 석조물의 전면 해체보수 ③ 기념관, 전시관, 박물관 등 신축, 복원, 이전 ④ 특수한 양식 등 고도의 전문성을 요하는 수리로 발주자가 인정한 경우 | I33: 2 | J33: 단순 | K33: 11.07 | M33: =I33&" "&J33 -> 2 단순 | N33: 11.07
A34: *. ‘지정유산 수리’라 함은 「국가유산수리 등에 관한 법률」 제2조제1호 가목 및 나목에 따른 국가유산수리를 말한다. | I34: 3 | J34: 단순 | K34: 10.33 | M34: =I34&" "&J34 -> 3 단순 | N34: 10.33
A35: **. ‘주변정비’라 함은 「국가유산수리 등에 관한 법률」 제2조제1호 다목에 따른 국가유산수리를 말한다. | I35: 5 | J35: 단순 | K35: 9.48 | M35: =I35&" "&J35 -> 5 단순 | N35: 9.48
A36: ***. ‘국가유산수리업’이라 함은 「국가유산수리 등에 관한 법률」제16조에 따른 국가유산수리업 중 ‘조경업, 보존과학업, 식물보호업, 단청공사업, 목공사업, 석공사업, 번와공사업, 미장공사업, 온돌공사업’을 말한다. | I36: 10 | J36: 단순 | K36: 8.43 | M36: =I36&" "&J36 -> 10 단순 | N36: 8.43
I37: 20 | J37: 단순 | K37: 7.5 | M37: =I37&" "&J37 -> 20 단순 | N37: 7.5
I38: 30 | J38: 단순 | K38: 7 | M38: =I38&" "&J38 -> 30 단순 | N38: 7
I39: 50 | J39: 단순 | K39: 6.43 | M39: =I39&" "&J39 -> 50 단순 | N39: 6.43
I40: 100 | J40: 단순 | K40: 5.72 | M40: =I40&" "&J40 -> 100 단순 | N40: 5.72
...

Sheet 산근2(손해보험공제요율)
B1: 손해배상보험료 산정
B2: : 국토교통부고시 제2019-997호에 근거 | P2: 5억원이하 | R2: 5억원초과10억원이하 | T2: 10억원초과20억원이하 | V2: 20억원초과30억원이하 | X2: 30억원초과50억원이하
B3: ○ 순용역금액 | E3: : | F3: =설계용역내역서!G6 -> 8545000 | I3: 원 | P3: =LOOKUP(ROUNDDOWN(V9*0.00000001,1),AL4:AL14,AM4:AM12)'
B4: ○ 적용요율 | E4: : | F4: 기본요율 + 적용가산요율
B5: ○ 적용가산요율 | E5: : | F5: 가산요율 x 표준공사기간초과일수/365일 | O5: '기초2(손해배상공제요율)'!$W$6:$AW$31
B6: ○ 공제요율 | E6: : | F6: =N6&", 표준공사기간 "&IF(N8=0,"이내","초과") -> 관람집회시설공사, 표준공사기간 이내 | M6: 공사구분 | N6: =VLOOKUP("공사종류(보험)",data!$A$1:$B$270,2,0) -> 관람집회시설공사
C7: 용역금액 | G7: 단위 | H7: 기본요율 | I7: 가산요율 | J7: 표준공사기간 | M7: 용역기간 | N7: =VLOOKUP(M7,data!$A$1:$B$270,2,0) -> 60 | O7: =VLOOKUP(M7,data!$A$1:$B$270,2,0)
C8: =VLOOKUP(IF(AND($N$9=$N$10,$N$9=5),2,O10),'기초2(손해배상공제요율)'!Q4:R8,2) -> 5억원이하 | G8: % | H8: =N11 -> 0.432 | I8: =N12 -> 0.069 | J8: =N13&"년" -> 3년 | M8: 표준공사기간 UP/down | N8: =IF((VLOOKUP(N6,('기초2(손해배상공제요율)'!$W$6:$AW$31),12))*365>=N7,0,N7-(VLOOKUP(N6,'기초2(손해배상공제요율)'!$W$6:$AW$31,12)*365)) -> 0
M9: 공사구간_낮은금액 | N9: =LOOKUP($F$3,$P$9:$P$14,$Q$9:$Q$14) -> 5 | O9: =IF(AND($N$9=$N$10),2,LOOKUP($N$9,$V$9:$V$13,$W$9:$W$13)) -> 2 | P9: 0 | Q9: 5 | S9: 0 | T9: 5 | V9: 5 | W9: 4
M10: 공사구간_높은금액 | N10: =LOOKUP($F$3,$S$9:$S$14,$T$9:$T$14) -> 5 | O10: =IF(AND($N$9=$N$10),2,LOOKUP($N$9,$V$9:$V$13,$W$9:$W$13)) -> 2 | P10: 500000000 | Q10: 5 | S10: 500000000 | T10: 10 | V10: 10 | W10: 6
M11: 기본요율 | N11: =VLOOKUP($N$6,'기초2(손해배상공제요율)'!$W$6:$AW$31,O9) -> 0.432 | P11: 1000000000 | Q11: 10 | S11: 1000000000 | T11: 20 | V11: 20 | W11: 8
B12: ○ 예정용역기간 : | E12: : | F12: =VLOOKUP(M7,data!$A$1:$B$270,2,0)&"일 ("&TEXT(VLOOKUP(M7,data!$A$1:$B$270,2,0)/30/12,"#,##0.00")&"년)" -> 60일 (0.17년) | M12: 가산요율 | N12: =VLOOKUP($N$6,'기초2(손해배상공제요율)'!$W$6:$AW$31,O9+1) -> 0.069 | P12: 2000000000 | Q12: 20 | S12: 2000000000 | T12: 30 | V12: 30 | W12: 10
B13: ○ 보험료산정 | M13: 표준공사기간 | N13: =VLOOKUP(N6,'기초2(손해배상공제요율)'!$W$6:$AW$31,12) -> 3 | P13: 3000000000 | Q13: 30 | S13: 3000000000 | T13: 40 | V13: 50 | W13: 10
C14: =F3 -> 8545000 | E14: x | F14: ="( "&H8&"% + "&I8&"% x "&N8&" / 365 ) =" -> ( 0.432% + 0.069% x 0 / 365 ) = | J14: =C14*(($H$8/100)+(($I$8/100)*0/365)) -> 36914.4 | M14: =F3*(N11+(N12*(N8/365))) -> 3691440 | N14: =F3*N11 -> 3691440 | P14: 5000000000 | Q14: 50 | S14: 5000000000 | T14: 50
H15: 계 | I15: = | J15: =SUM(J14:J14) -> 36914.4
B17: ○ 손해배상보험료 | G17: = | H17: =ROUNDDOWN(J15,-3) -> 36000

Sheet 기초2(손해배상공제요율)
A1: ▨ 용역손해배상보험 또는 공제 요율
A2: 1.적용요율 = 기본요율 + 적용가산요율
A3: 2.적용가산요율 = 가산요율 x 표준공사기간초과일수/365
A4: ⊙ | B4: ='산근2(손해보험공제요율)'!F6 -> 관람집회시설공사, 표준공사기간 이내 | Q4: 2 | R4: 5억원이하 | X4: 5억원이하 | Z4: 5억원초과10억원이하 | AB4: 10억원초과20억원이하 | AD4: 20억원초과30억원이하 | AF4: 30억원초과50억원이하
A5: ⊙ | B5: 요율산출 : | C5: =(('산근2(손해보험공제요율)'!$H$8)+(('산근2(손해보험공제요율)'!$I$8)*0/365)) -> 0.432 | D5: % | Q5: 3 | R5: 5억원초과10억원이하 | X5: 기본요율 | Y5: 가산요율 | Z5: 기본요율 | AA5: 가산요율 | AB5: 기본요율 | AC5: 가산요율 | AD5: 기본요율 | AE5: 가산요율 | AF5: 기본요율 | AG5: 가산요율
A6: 공 사 종 류 | B6: 용 역 금 액 | L6: 표준 공사 기간 | Q6: 4 | R6: 10억원초과20억원이하 | W6: 교량공사 | X6: 0.722 | Y6: 0.114 | Z6: 0.7 | AA6: 0.112 | AB6: 0.678 | AC6: 0.109 | AD6: 0.657 | AE6: 0.105 | AF6: 0.635 | AG6: 0.102 | AH6: 3
B7: 5억원이하 | D7: 5억원초과10억원이하 | F7: 10억원초과20억원이하 | H7: 20억원초과30억원이하 | J7: 30억원초과50억원이하 | Q7: 5 | R7: 20억원초과30억원이하 | W7: 간척공사 | X7: 0.735 | Y7: 0.117 | Z7: 0.714 | AA7: 0.114 | AB7: 0.691 | AC7: 0.111 | AD7: 0.669 | AE7: 0.108 | AF7: 0.648 | AG7: 0.103 | AH7: 5
B8: 기본요율 | C8: 가산요율 | D8: 기본요율 | E8: 가산요율 | F8: 기본요율 | G8: 가산요율 | H8: 기본요율 | I8: 가산요율 | J8: 기본요율 | K8: 가산요율 | Q8: 6 | R8: 30억원초과50억원이하 | W8: 공동주택건설공사 | X8: 0.558 | Y8: 0.089 | Z8: 0.542 | AA8: 0.086 | AB8: 0.525 | AC8: 0.085 | AD8: 0.508 | AE8: 0.082 | AF8: 0.492 | AG8: 0.078 | AH8: 3
A9: 1 | B9: 2 | C9: 3 | D9: 4 | E9: 5 | F9: 6 | G9: 7 | H9: 8 | I9: 9 | J9: 10 | K9: 11 | L9: 12 | W9: 공용청사건설공사 | X9: 0.52 | Y9: 0.083 | Z9: 0.503 | AA9: 0.082 | AB9: 0.488 | AC9: 0.078 | AD9: 0.472 | AE9: 0.077 | AF9: 0.457 | AG9: 0.072 | AH9: 3
A10: 교량공사 | B10: 0.722 | C10: 0.114 | D10: 0.7 | E10: 0.112 | F10: 0.678 | G10: 0.109 | H10: 0.657 | I10: 0.105 | J10: 0.635 | K10: 0.102 | L10: 3 | W10: 공항건설공사 | X10: 0.817 | Y10: 0.129 | Z10: 0.792 | AA10: 0.128 | AB10: 0.769 | AC10: 0.123 | AD10: 0.743 | AE10: 0.118 | AF10: 0.718 | AG10: 0.114 | AH10: 5
A11: 공항건설공사 | B11: 0.817 | C11: 0.129 | D11: 0.792 | E11: 0.128 | F11: 0.769 | G11: 0.123 | H11: 0.743 | I11: 0.118 | J11: 0.718 | K11: 0.114 | L11: 5 | W11: 관람집회시설공사 | X11: 0.432 | Y11: 0.069 | Z11: 0.42 | AA11: 0.068 | AB11: 0.406 | AC11: 0.065 | AD11: 0.394 | AE11: 0.063 | AF11: 0.382 | AG11: 0.062 | AH11: 3
A12: 댐축조공사 | B12: 0.903 | C12: 0.145 | D12: 0.875 | E12: 0.14 | F12: 0.848 | G12: 0.135 | H12: 0.82 | I12: 0.132 | J12: 0.794 | K12: 0.128 | L12: 5 | W12: 댐축조공사 | X12: 0.903 | Y12: 0.145 | Z12: 0.875 | AA12: 0.14 | AB12: 0.848 | AC12: 0.135 | AD12: 0.82 | AE12: 0.132 | AF12: 0.794 | AG12: 0.128 | AH12: 5
A13: 도로공사 | B13: 0.649 | C13: 0.105 | D13: 0.629 | E13: 0.1 | F13: 0.609 | G13: 0.098 | H13: 0.591 | I13: 0.094 | J13: 0.571 | K13: 0.091 | L13: 3 | W13: 도로공사 | X13: 0.649 | Y13: 0.105 | Z13: 0.629 | AA13: 0.1 | AB13: 0.609 | AC13: 0.098 | AD13: 0.591 | AE13: 0.094 | AF13: 0.571 | AG13: 0.091 | AH13: 3
A14: 에너지저장시설공사 | B14: 0.649 | C14: 0.105 | D14: 0.629 | E14: 0.1 | F14: 0.609 | G14: 0.098 | H14: 0.591 | I14: 0.094 | J14: 0.571 | K14: 0.091 | L14: 3 | W14: 발전소건설공사 | X14: 0.769 | Y14: 0.123 | Z14: 0.746 | AA14: 0.118 | AB14: 0.723 | AC14: 0.115 | AD14: 0.7 | AE14: 0.112 | AF14: 0.677 | AG14: 0.109 | AH14: 3
A15: 간척공사 | B15: 0.735 | C15: 0.117 | D15: 0.714 | E15: 0.114 | F15: 0.691 | G15: 0.111 | H15: 0.669 | I15: 0.108 | J15: 0.648 | K15: 0.103 | L15: 5 | W15: 변전공사 | X15: 0.538 | Y15: 0.086 | Z15: 0.523 | AA15: 0.083 | AB15: 0.506 | AC15: 0.082 | AD15: 0.489 | AE15: 0.078 | AF15: 0.474 | AG15: 0.077 | AH15: 2
A16: 항만공사 | B16: 0.735 | C16: 0.117 | D16: 0.714 | E16: 0.114 | F16: 0.691 | G16: 0.111 | H16: 0.669 | I16: 0.108 | J16: 0.648 | K16: 0.103 | L16: 5 | W16: 상수도(정수장포함)건설공사 | X16: 0.843 | Y16: 0.134 | Z16: 0.818 | AA16: 0.131 | AB16: 0.792 | AC16: 0.128 | AD16: 0.768 | AE16: 0.123 | AF16: 0.742 | AG16: 0.118 | AH16: 3
A17: 철도공사 | B17: 0.577 | C17: 0.091 | D17: 0.56 | E17: 0.089 | F17: 0.543 | G17: 0.086 | H17: 0.525 | I17: 0.085 | J17: 0.508 | K17: 0.082 | L17: 3 | W17: 송전공사 | X17: 0.538 | Y17: 0.086 | Z17: 0.523 | AA17: 0.083 | AB17: 0.506 | AC17: 0.082 | AD17: 0.489 | AE17: 0.078 | AF17: 0.474 | AG17: 0.077 | AH17: 2
A18: 지하철공사 | B18: 0.903 | C18: 0.145 | D18: 0.875 | E18: 0.14 | F18: 0.848 | G18: 0.135 | H18: 0.82 | I18: 0.132 | J18: 0.794 | K18: 0.128 | L18: 4 | W18: 쓰레기소각로건설공사 | X18: 1 | Y18: 0.16 | Z18: 0.969 | AA18: 0.155 | AB18: 0.94 | AC18: 0.151 | AD18: 0.909 | AE18: 0.146 | AF18: 0.88 | AG18: 0.142 | AH18: 2
A19: 터널공사 | B19: 0.903 | C19: 0.145 | D19: 0.875 | E19: 0.14 | F19: 0.848 | G19: 0.135 | H19: 0.82 | I19: 0.132 | J19: 0.794 | K19: 0.128 | L19: 4 | W19: 에너지저장시설공사 | X19: 0.649 | Y19: 0.105 | Z19: 0.629 | AA19: 0.1 | AB19: 0.609 | AC19: 0.098 | AD19: 0.591 | AE19: 0.094 | AF19: 0.571 | AG19: 0.091 | AH19: 3
A20: 발전소건설공사 | B20: 0.769 | C20: 0.123 | D20: 0.746 | E20: 0.118 | F20: 0.723 | G20: 0.115 | H20: 0.7 | I20: 0.112 | J20: 0.677 | K20: 0.109 | L20: 3 | W20: 전시시설공사 | X20: 0.432 | Y20: 0.069 | Z20: 0.42 | AA20: 0.068 | AB20: 0.406 | AC20: 0.065 | AD20: 0.394 | AE20: 0.063 | AF20: 0.382 | AG20: 0.062 | AH20: 2
A21: 쓰레기소각로건설공사 | B21: 1 | C21: 0.16 | D21: 0.969 | E21: 0.155 | F21: 0.94 | G21: 0.151 | H21: 0.909 | I21: 0.146 | J21: 0.88 | K21: 0.142 | L21: 2 | W21: 지하철공사 | X21: 0.903 | Y21: 0.145 | Z21: 0.875 | AA21: 0.14 | AB21: 0.848 | AC21: 0.135 | AD21: 0.82 | AE21: 0.132 | AF21: 0.794 | AG21: 0.128 | AH21: 4
... A27: 전시시설공사 | B27: 0.432 | C27: 0.069 | D27: 0.42 | E27: 0.068 | F27: 0.406 | G27: 0.065 | H27: 0.394 | I27: 0.063 | J27: 0.382 | K27: 0.062 | L27: 2 | W27: 항만공사 | X27: 0.735 | Y27: 0.117 | Z27: 0.714 | AA27: 0.114 | AB27: 0.691 | AC27: 0.111 | AD27: 0.669 | AE27: 0.108 | AF27: 0.648 | AG27: 0.103 | AH27: 5
A28: 공용청사건설공사 | B28: 0.52 | C28: 0.083 | D28: 0.503 | E28: 0.082 | F28: 0.488 | G28: 0.078 | H28: 0.472 | I28: 0.077 | J28: 0.457 | K28: 0.072 | L28: 3
A29: 송전공사 | B29: 0.538 | C29: 0.086 | D29: 0.523 | E29: 0.083 | F29: 0.506 | G29: 0.082 | H29: 0.489 | I29: 0.078 | J29: 0.474 | K29: 0.077 | L29: 2 | X29: =AND(SEARCH('산근2(손해보험공제요율)'!N6,W6:W27),'산근2(손해보험공제요율)'!N11) -> #VALUE!
A30: 변전공사 | B30: 0.538 | C30: 0.086 | D30: 0.523 | E30: 0.083 | F30: 0.506 | G30: 0.082 | H30: 0.489 | I30: 0.078 | J30: 0.474 | K30: 0.077 | L30: 2 | X30: {=INDEX(B10:K31,MATCH(1,('산근2(손해보험공제요율)'!N6)*('산근2(손해보험공제요율)'!N11),0),0)} -> #VALUE!
A31: 공동주택건설공사 | B31: 0.558 | C31: 0.089 | D31: 0.542 | E31: 0.086 | F31: 0.525 | G31: 0.085 | H31: 0.508 | I31: 0.082 | J31: 0.492 | K31: 0.078 | L31: 3
A32: 평 균 | B32: =AVERAGE(B10:B31) -> 0.7085 | C32: =AVERAGE(C10:C31) -> 0.11318182 | D32: =AVERAGE(D10:D31) -> 0.68709091 | E32: =AVERAGE(E10:E31) -> 0.10986364 | F32: =AVERAGE(F10:F31) -> 0.66572727 | G32: =AVERAGE(G10:G31) -> 0.10663636 | H32: =AVERAGE(H10:H31) -> 0.6445 | I32: =AVERAGE(I10:I31) -> 0.10327273 | ... L32: =AVERAGE(L10:L31) -> 3.1363636

Sheet 산근1(현황측량)
A1: [산출근거][측량산출근거]
B2: 1.지형현황측량
B3: o 지형 유형에 따른 증감계수(K)
B4: 지형구분 | C4: 증가계수
B5: 밀집시가지 | C5: 2.8
B6: 시가지 | C6: 2.15
B7: 평지 | C7: 1
B8: 구릉지 | C8: 1.25
B9: 산지 | C9: 1.3
B11: o 축척에 따른 증감계수(S)
B12: 축 척 | C12: 1/250 | D12: 1/500 | E12: 1/1,000 | F12: 1/2,500
B13: 증감계수 | C13: 1.6 | D13: 1 | E13: 0.65 | F13: 0.54
B15: o 작업량에 따른 증감계수(P)
B16: 작업량(㎡) | C16: 2만 | D16: 5만 | E16: 10만 | F16: 15만 | G16: 20만
B17: 증감계수 | C17: 1.8 | D17: 1.2 | E17: 1 | F17: 0.93 | G17: 0.9
B19: o 작업종류에 따른 계수(T) | G19: - 작업량 P = 0.8 + {2/작업량(면적)}
B20: 작업종류 | C20: 신규측량 | D20: 수정측량 | G20: - 작업량이 20만㎡ 이상인 경우에도 작업량계수(P)는 0.90으로 적용한다.
B21: 계 수 | C21: 1 | D21: 1.25 | G21: P = | H21: 0.8 | I21: + | J21: 2 | K21: =B25 -> 1000 | M21: 1.8
B23: o 지형현황측량 작업량
B24: 면적(㎡) | C24: 표준작업량
B25: 1000 | C25: =B25/C30 -> 0.01
B26: ※ 하천연장 L= | C26: 2000
B27: 평균하폭 B= | C27: 70
E28: 총증감계수 = 표준작업량*K*S*P*T = | H28: =C25 -> 0.01 | I28: × | J28: =C9 -> 1.3 | K28: × | L28: =C13 -> 1.6 | M28: × | N28: =M21 -> 1.8 | O28: × | P28: =C21 -> 1 | Q28: = | R28: =H28*J28*L28*N28*P28 -> 0.03744
G29: (표준작업량) | J29: (K) | L29: (S) | N29: (P) | P29: (T)
C30: 100000
C31: (기준)
